2024-12-26 22:24:38,601 - ERROR - 
Endpoint: signup
URL: No URL
Method: No method
Data: No request data
Error: 500: 400: User already exists
Traceback: Traceback (most recent call last):
  File "/home/charbel/Desktop/recipe_recommendation-main/api/api.py", line 172, in signup
    raise HTTPException(status_code=400, detail="User already exists")
fastapi.exceptions.HTTPException: 400: User already exists

During handling of the above exception, another exception occurred:

Traceback (most recent call last):
  File "/home/charbel/Desktop/recipe_recommendation-main/api/api.py", line 26, in wrapper
    return await func(*args, **kwargs)
           ^^^^^^^^^^^^^^^^^^^^^^^^^^^
  File "/home/charbel/Desktop/recipe_recommendation-main/api/api.py", line 178, in signup
    raise HTTPException(status_code=500, detail=str(e))
fastapi.exceptions.HTTPException: 500: 400: User already exists

2024-12-26 22:24:44,392 - ERROR - 
Endpoint: signup
URL: No URL
Method: No method
Data: No request data
Error: 500: 400: User already exists
Traceback: Traceback (most recent call last):
  File "/home/charbel/Desktop/recipe_recommendation-main/api/api.py", line 172, in signup
    raise HTTPException(status_code=400, detail="User already exists")
fastapi.exceptions.HTTPException: 400: User already exists

During handling of the above exception, another exception occurred:

Traceback (most recent call last):
  File "/home/charbel/Desktop/recipe_recommendation-main/api/api.py", line 26, in wrapper
    return await func(*args, **kwargs)
           ^^^^^^^^^^^^^^^^^^^^^^^^^^^
  File "/home/charbel/Desktop/recipe_recommendation-main/api/api.py", line 178, in signup
    raise HTTPException(status_code=500, detail=str(e))
fastapi.exceptions.HTTPException: 500: 400: User already exists

2024-12-26 22:25:56,539 - ERROR - 
Endpoint: signup
URL: No URL
Method: No method
Data: No request data
Error: 500: 400: User already exists
Traceback: Traceback (most recent call last):
  File "/home/charbel/Desktop/recipe_recommendation-main/api/api.py", line 172, in signup
    raise HTTPException(status_code=400, detail="User already exists")
fastapi.exceptions.HTTPException: 400: User already exists

During handling of the above exception, another exception occurred:

Traceback (most recent call last):
  File "/home/charbel/Desktop/recipe_recommendation-main/api/api.py", line 26, in wrapper
    return await func(*args, **kwargs)
           ^^^^^^^^^^^^^^^^^^^^^^^^^^^
  File "/home/charbel/Desktop/recipe_recommendation-main/api/api.py", line 178, in signup
    raise HTTPException(status_code=500, detail=str(e))
fastapi.exceptions.HTTPException: 500: 400: User already exists

2024-12-26 22:26:14,983 - ERROR - 
Endpoint: signup
URL: No URL
Method: No method
Data: No request data
Error: 500: 400: User already exists
Traceback: Traceback (most recent call last):
  File "/home/charbel/Desktop/recipe_recommendation-main/api/api.py", line 172, in signup
    raise HTTPException(status_code=400, detail="User already exists")
fastapi.exceptions.HTTPException: 400: User already exists

During handling of the above exception, another exception occurred:

Traceback (most recent call last):
  File "/home/charbel/Desktop/recipe_recommendation-main/api/api.py", line 26, in wrapper
    return await func(*args, **kwargs)
           ^^^^^^^^^^^^^^^^^^^^^^^^^^^
  File "/home/charbel/Desktop/recipe_recommendation-main/api/api.py", line 178, in signup
    raise HTTPException(status_code=500, detail=str(e))
fastapi.exceptions.HTTPException: 500: 400: User already exists

