2024-12-25 20:27:48,982 - ERROR - 
Endpoint: predict
URL: No URL
Method: No method
Data: No request data
Error: 500: name 'df' is not defined
Traceback: Traceback (most recent call last):
  File "/home/charbel/Desktop/recipe_recommendation-main/api/api.py", line 147, in predict
    recipe_titles, details = predict_recipes(data, df)
                                                   ^^
NameError: name 'df' is not defined

During handling of the above exception, another exception occurred:

Traceback (most recent call last):
  File "/home/charbel/Desktop/recipe_recommendation-main/api/api.py", line 23, in wrapper
    return await func(*args, **kwargs)
           ^^^^^^^^^^^^^^^^^^^^^^^^^^^
  File "/home/charbel/Desktop/recipe_recommendation-main/api/api.py", line 150, in predict
    raise HTTPException(status_code=500, detail=str(e))
fastapi.exceptions.HTTPException: 500: name 'df' is not defined

2024-12-25 21:22:58,791 - ERROR - 
Endpoint: signup
URL: No URL
Method: No method
Data: No request data
Error: 500: BaseModel.__init__() takes 1 positional argument but 2 were given
Traceback: Traceback (most recent call last):
  File "/home/charbel/Desktop/recipe_recommendation-main/api/api.py", line 160, in signup
    user = User(user_input)
           ^^^^^^^^^^^^^^^^
TypeError: BaseModel.__init__() takes 1 positional argument but 2 were given

During handling of the above exception, another exception occurred:

Traceback (most recent call last):
  File "/home/charbel/Desktop/recipe_recommendation-main/api/api.py", line 24, in wrapper
    return await func(*args, **kwargs)
           ^^^^^^^^^^^^^^^^^^^^^^^^^^^
  File "/home/charbel/Desktop/recipe_recommendation-main/api/api.py", line 174, in signup
    raise HTTPException(status_code=500, detail=str(e))
fastapi.exceptions.HTTPException: 500: BaseModel.__init__() takes 1 positional argument but 2 were given

2024-12-25 21:24:46,030 - ERROR - 
Endpoint: signup
URL: No URL
Method: No method
Data: No request data
Error: 500: 400: User already exists
Traceback: Traceback (most recent call last):
  File "/home/charbel/Desktop/recipe_recommendation-main/api/api.py", line 165, in signup
    raise HTTPException(status_code=400, detail="User already exists")
fastapi.exceptions.HTTPException: 400: User already exists

During handling of the above exception, another exception occurred:

Traceback (most recent call last):
  File "/home/charbel/Desktop/recipe_recommendation-main/api/api.py", line 24, in wrapper
    return await func(*args, **kwargs)
           ^^^^^^^^^^^^^^^^^^^^^^^^^^^
  File "/home/charbel/Desktop/recipe_recommendation-main/api/api.py", line 171, in signup
    raise HTTPException(status_code=500, detail=str(e))
fastapi.exceptions.HTTPException: 500: 400: User already exists

2024-12-25 21:24:54,182 - ERROR - 
Endpoint: signup
URL: No URL
Method: No method
Data: No request data
Error: 500: 400: User already exists
Traceback: Traceback (most recent call last):
  File "/home/charbel/Desktop/recipe_recommendation-main/api/api.py", line 165, in signup
    raise HTTPException(status_code=400, detail="User already exists")
fastapi.exceptions.HTTPException: 400: User already exists

During handling of the above exception, another exception occurred:

Traceback (most recent call last):
  File "/home/charbel/Desktop/recipe_recommendation-main/api/api.py", line 24, in wrapper
    return await func(*args, **kwargs)
           ^^^^^^^^^^^^^^^^^^^^^^^^^^^
  File "/home/charbel/Desktop/recipe_recommendation-main/api/api.py", line 171, in signup
    raise HTTPException(status_code=500, detail=str(e))
fastapi.exceptions.HTTPException: 500: 400: User already exists

2024-12-25 21:25:41,882 - ERROR - 
Endpoint: signup
URL: No URL
Method: No method
Data: No request data
Error: 500: 400: User already exists
Traceback: Traceback (most recent call last):
  File "/home/charbel/Desktop/recipe_recommendation-main/api/api.py", line 165, in signup
    raise HTTPException(status_code=400, detail="User already exists")
fastapi.exceptions.HTTPException: 400: User already exists

During handling of the above exception, another exception occurred:

Traceback (most recent call last):
  File "/home/charbel/Desktop/recipe_recommendation-main/api/api.py", line 24, in wrapper
    return await func(*args, **kwargs)
           ^^^^^^^^^^^^^^^^^^^^^^^^^^^
  File "/home/charbel/Desktop/recipe_recommendation-main/api/api.py", line 171, in signup
    raise HTTPException(status_code=500, detail=str(e))
fastapi.exceptions.HTTPException: 500: 400: User already exists

2024-12-25 21:28:15,116 - ERROR - 
Endpoint: signup
URL: No URL
Method: No method
Data: No request data
Error: 500: 400: User already exists
Traceback: Traceback (most recent call last):
  File "/home/charbel/Desktop/recipe_recommendation-main/api/api.py", line 165, in signup
    raise HTTPException(status_code=400, detail="User already exists")
fastapi.exceptions.HTTPException: 400: User already exists

During handling of the above exception, another exception occurred:

Traceback (most recent call last):
  File "/home/charbel/Desktop/recipe_recommendation-main/api/api.py", line 24, in wrapper
    return await func(*args, **kwargs)
           ^^^^^^^^^^^^^^^^^^^^^^^^^^^
  File "/home/charbel/Desktop/recipe_recommendation-main/api/api.py", line 171, in signup
    raise HTTPException(status_code=500, detail=str(e))
fastapi.exceptions.HTTPException: 500: 400: User already exists

2024-12-25 22:07:08,415 - ERROR - 
Endpoint: predict
URL: No URL
Method: No method
Data: No request data
Error: 500: name 'df' is not defined
Traceback: Traceback (most recent call last):
  File "/home/charbel/Desktop/recipe_recommendation-main/api/api.py", line 148, in predict
    recipe_titles, details = predict_recipes(data, df)
                                                   ^^
NameError: name 'df' is not defined

During handling of the above exception, another exception occurred:

Traceback (most recent call last):
  File "/home/charbel/Desktop/recipe_recommendation-main/api/api.py", line 24, in wrapper
    return await func(*args, **kwargs)
           ^^^^^^^^^^^^^^^^^^^^^^^^^^^
  File "/home/charbel/Desktop/recipe_recommendation-main/api/api.py", line 151, in predict
    raise HTTPException(status_code=500, detail=str(e))
fastapi.exceptions.HTTPException: 500: name 'df' is not defined

2024-12-25 23:15:57,748 - ERROR - 
Endpoint: predict
URL: No URL
Method: No method
Data: No request data
Error: 500: name 'df' is not defined
Traceback: Traceback (most recent call last):
  File "/home/charbel/Desktop/recipe_recommendation-main/api/api.py", line 148, in predict
    recipe_titles, details = predict_recipes(data, df)
                                                   ^^
NameError: name 'df' is not defined

During handling of the above exception, another exception occurred:

Traceback (most recent call last):
  File "/home/charbel/Desktop/recipe_recommendation-main/api/api.py", line 24, in wrapper
    try:
         
  File "/home/charbel/Desktop/recipe_recommendation-main/api/api.py", line 151, in predict
    raise HTTPException(status_code=500, detail=str(e))
fastapi.exceptions.HTTPException: 500: name 'df' is not defined

2024-12-25 23:16:12,912 - ERROR - 
Endpoint: signup
URL: No URL
Method: No method
Data: No request data
Error: 500: 400: User already exists
Traceback: Traceback (most recent call last):
  File "/home/charbel/Desktop/recipe_recommendation-main/api/api.py", line 165, in signup
    raise HTTPException(status_code=400, detail="User already exists")
fastapi.exceptions.HTTPException: 400: User already exists

During handling of the above exception, another exception occurred:

Traceback (most recent call last):
  File "/home/charbel/Desktop/recipe_recommendation-main/api/api.py", line 24, in wrapper
    try:
         
  File "/home/charbel/Desktop/recipe_recommendation-main/api/api.py", line 171, in signup
    raise HTTPException(status_code=500, detail=str(e))
fastapi.exceptions.HTTPException: 500: 400: User already exists

2024-12-25 23:16:32,124 - ERROR - 
Endpoint: signup
URL: No URL
Method: No method
Data: No request data
Error: 500: 400: User already exists
Traceback: Traceback (most recent call last):
  File "/home/charbel/Desktop/recipe_recommendation-main/api/api.py", line 165, in signup
    raise HTTPException(status_code=400, detail="User already exists")
fastapi.exceptions.HTTPException: 400: User already exists

During handling of the above exception, another exception occurred:

Traceback (most recent call last):
  File "/home/charbel/Desktop/recipe_recommendation-main/api/api.py", line 24, in wrapper
    try:
         
  File "/home/charbel/Desktop/recipe_recommendation-main/api/api.py", line 171, in signup
    raise HTTPException(status_code=500, detail=str(e))
fastapi.exceptions.HTTPException: 500: 400: User already exists

2024-12-25 23:16:38,417 - ERROR - 
Endpoint: signup
URL: No URL
Method: No method
Data: No request data
Error: 500: 400: User already exists
Traceback: Traceback (most recent call last):
  File "/home/charbel/Desktop/recipe_recommendation-main/api/api.py", line 165, in signup
    raise HTTPException(status_code=400, detail="User already exists")
fastapi.exceptions.HTTPException: 400: User already exists

During handling of the above exception, another exception occurred:

Traceback (most recent call last):
  File "/home/charbel/Desktop/recipe_recommendation-main/api/api.py", line 24, in wrapper
    try:
         
  File "/home/charbel/Desktop/recipe_recommendation-main/api/api.py", line 171, in signup
    raise HTTPException(status_code=500, detail=str(e))
fastapi.exceptions.HTTPException: 500: 400: User already exists

2024-12-25 23:19:49,038 - ERROR - 
Endpoint: signup
URL: No URL
Method: No method
Data: No request data
Error: 500: 400: User already exists
Traceback: Traceback (most recent call last):
  File "/home/charbel/Desktop/recipe_recommendation-main/api/api.py", line 165, in signup
    raise HTTPException(status_code=400, detail="User already exists")
fastapi.exceptions.HTTPException: 400: User already exists

During handling of the above exception, another exception occurred:

Traceback (most recent call last):
  File "/home/charbel/Desktop/recipe_recommendation-main/api/api.py", line 25, in wrapper
    return await func(*args, **kwargs)
           ^^^^^^^^^^^^^^^^^^^^^^^^^^^
  File "/home/charbel/Desktop/recipe_recommendation-main/api/api.py", line 171, in signup
    raise HTTPException(status_code=500, detail=str(e))
fastapi.exceptions.HTTPException: 500: 400: User already exists

2024-12-25 23:19:49,056 - ERROR - 
Endpoint: add_recipe_endpoint
URL: No URL
Method: No method
Data: No request data
Error: coroutine raised StopIteration
Traceback: Traceback (most recent call last):
  File "/home/charbel/Desktop/recipe_recommendation-main/api/auth_utils.py", line 46, in wrapper
    request: Request = next(arg for arg in args if isinstance(arg, Request))
                       ^^^^^^^^^^^^^^^^^^^^^^^^^^^^^^^^^^^^^^^^^^^^^^^^^^^^^
StopIteration

The above exception was the direct cause of the following exception:

Traceback (most recent call last):
  File "/home/charbel/Desktop/recipe_recommendation-main/api/api.py", line 25, in wrapper
    return await func(*args, **kwargs)
           ^^^^^^^^^^^^^^^^^^^^^^^^^^^
RuntimeError: coroutine raised StopIteration

2024-12-25 23:20:06,605 - ERROR - 
Endpoint: signup
URL: No URL
Method: No method
Data: No request data
Error: 500: 400: User already exists
Traceback: Traceback (most recent call last):
  File "/home/charbel/Desktop/recipe_recommendation-main/api/api.py", line 165, in signup
    raise HTTPException(status_code=400, detail="User already exists")
fastapi.exceptions.HTTPException: 400: User already exists

During handling of the above exception, another exception occurred:

Traceback (most recent call last):
  File "/home/charbel/Desktop/recipe_recommendation-main/api/api.py", line 25, in wrapper
    return await func(*args, **kwargs)
           ^^^^^^^^^^^^^^^^^^^^^^^^^^^
  File "/home/charbel/Desktop/recipe_recommendation-main/api/api.py", line 171, in signup
    raise HTTPException(status_code=500, detail=str(e))
fastapi.exceptions.HTTPException: 500: 400: User already exists

2024-12-25 23:20:06,616 - ERROR - 
Endpoint: add_recipe_endpoint
URL: No URL
Method: No method
Data: No request data
Error: coroutine raised StopIteration
Traceback: Traceback (most recent call last):
  File "/home/charbel/Desktop/recipe_recommendation-main/api/auth_utils.py", line 46, in wrapper
    request: Request = next(arg for arg in args if isinstance(arg, Request))
                       ^^^^^^^^^^^^^^^^^^^^^^^^^^^^^^^^^^^^^^^^^^^^^^^^^^^^^
StopIteration

The above exception was the direct cause of the following exception:

Traceback (most recent call last):
  File "/home/charbel/Desktop/recipe_recommendation-main/api/api.py", line 25, in wrapper
    return await func(*args, **kwargs)
           ^^^^^^^^^^^^^^^^^^^^^^^^^^^
RuntimeError: coroutine raised StopIteration

2024-12-25 23:20:08,523 - ERROR - 
Endpoint: signup
URL: No URL
Method: No method
Data: No request data
Error: 500: 400: User already exists
Traceback: Traceback (most recent call last):
  File "/home/charbel/Desktop/recipe_recommendation-main/api/api.py", line 165, in signup
    raise HTTPException(status_code=400, detail="User already exists")
fastapi.exceptions.HTTPException: 400: User already exists

During handling of the above exception, another exception occurred:

Traceback (most recent call last):
  File "/home/charbel/Desktop/recipe_recommendation-main/api/api.py", line 25, in wrapper
    return await func(*args, **kwargs)
           ^^^^^^^^^^^^^^^^^^^^^^^^^^^
  File "/home/charbel/Desktop/recipe_recommendation-main/api/api.py", line 171, in signup
    raise HTTPException(status_code=500, detail=str(e))
fastapi.exceptions.HTTPException: 500: 400: User already exists

2024-12-25 23:20:08,533 - ERROR - 
Endpoint: add_recipe_endpoint
URL: No URL
Method: No method
Data: No request data
Error: coroutine raised StopIteration
Traceback: Traceback (most recent call last):
  File "/home/charbel/Desktop/recipe_recommendation-main/api/auth_utils.py", line 46, in wrapper
    request: Request = next(arg for arg in args if isinstance(arg, Request))
                       ^^^^^^^^^^^^^^^^^^^^^^^^^^^^^^^^^^^^^^^^^^^^^^^^^^^^^
StopIteration

The above exception was the direct cause of the following exception:

Traceback (most recent call last):
  File "/home/charbel/Desktop/recipe_recommendation-main/api/api.py", line 25, in wrapper
    return await func(*args, **kwargs)
           ^^^^^^^^^^^^^^^^^^^^^^^^^^^
RuntimeError: coroutine raised StopIteration

2024-12-25 23:20:36,876 - ERROR - 
Endpoint: add_recipe_endpoint
URL: No URL
Method: No method
Data: No request data
Error: coroutine raised StopIteration
Traceback: Traceback (most recent call last):
  File "/home/charbel/Desktop/recipe_recommendation-main/api/auth_utils.py", line 46, in wrapper
    request: Request = next(arg for arg in args if isinstance(arg, Request))
                       ^^^^^^^^^^^^^^^^^^^^^^^^^^^^^^^^^^^^^^^^^^^^^^^^^^^^^
StopIteration

The above exception was the direct cause of the following exception:

Traceback (most recent call last):
  File "/home/charbel/Desktop/recipe_recommendation-main/api/api.py", line 25, in wrapper
    return await func(*args, **kwargs)
           ^^^^^^^^^^^^^^^^^^^^^^^^^^^
RuntimeError: coroutine raised StopIteration

2024-12-25 23:28:55,789 - ERROR - 
Endpoint: login
URL: No URL
Method: No method
Data: No request data
Error: 500: name 'timedelta' is not defined
Traceback: Traceback (most recent call last):
  File "/home/charbel/Desktop/recipe_recommendation-main/api/api.py", line 191, in login
    access_token_expires = timedelta(minutes=ACCESS_TOKEN_EXPIRE_MINUTES)
                           ^^^^^^^^^
NameError: name 'timedelta' is not defined

During handling of the above exception, another exception occurred:

Traceback (most recent call last):
  File "/home/charbel/Desktop/recipe_recommendation-main/api/api.py", line 25, in wrapper
    return await func(*args, **kwargs)
           ^^^^^^^^^^^^^^^^^^^^^^^^^^^
  File "/home/charbel/Desktop/recipe_recommendation-main/api/api.py", line 209, in login
    raise HTTPException(status_code=500, detail=str(e))
fastapi.exceptions.HTTPException: 500: name 'timedelta' is not defined

2024-12-25 23:29:59,310 - ERROR - 
Endpoint: signup
URL: No URL
Method: No method
Data: No request data
Error: 500: 400: User already exists
Traceback: Traceback (most recent call last):
  File "/home/charbel/Desktop/recipe_recommendation-main/api/api.py", line 165, in signup
    raise HTTPException(status_code=400, detail="User already exists")
fastapi.exceptions.HTTPException: 400: User already exists

During handling of the above exception, another exception occurred:

Traceback (most recent call last):
  File "/home/charbel/Desktop/recipe_recommendation-main/api/api.py", line 25, in wrapper
    return await func(*args, **kwargs)
           ^^^^^^^^^^^^^^^^^^^^^^^^^^^
  File "/home/charbel/Desktop/recipe_recommendation-main/api/api.py", line 171, in signup
    raise HTTPException(status_code=500, detail=str(e))
fastapi.exceptions.HTTPException: 500: 400: User already exists

2024-12-25 23:29:59,348 - ERROR - 
Endpoint: login
URL: No URL
Method: No method
Data: No request data
Error: 500: name 'timedelta' is not defined
Traceback: Traceback (most recent call last):
  File "/home/charbel/Desktop/recipe_recommendation-main/api/api.py", line 191, in login
    access_token_expires = timedelta(minutes=ACCESS_TOKEN_EXPIRE_MINUTES)
                           ^^^^^^^^^
NameError: name 'timedelta' is not defined

During handling of the above exception, another exception occurred:

Traceback (most recent call last):
  File "/home/charbel/Desktop/recipe_recommendation-main/api/api.py", line 25, in wrapper
    return await func(*args, **kwargs)
           ^^^^^^^^^^^^^^^^^^^^^^^^^^^
  File "/home/charbel/Desktop/recipe_recommendation-main/api/api.py", line 209, in login
    raise HTTPException(status_code=500, detail=str(e))
fastapi.exceptions.HTTPException: 500: name 'timedelta' is not defined

2024-12-25 23:31:05,784 - ERROR - 
Endpoint: signup
URL: No URL
Method: No method
Data: No request data
Error: 500: 400: User already exists
Traceback: Traceback (most recent call last):
  File "/home/charbel/Desktop/recipe_recommendation-main/api/api.py", line 165, in signup
    raise HTTPException(status_code=400, detail="User already exists")
fastapi.exceptions.HTTPException: 400: User already exists

During handling of the above exception, another exception occurred:

Traceback (most recent call last):
  File "/home/charbel/Desktop/recipe_recommendation-main/api/api.py", line 25, in wrapper
    return await func(*args, **kwargs)
           ^^^^^^^^^^^^^^^^^^^^^^^^^^^
  File "/home/charbel/Desktop/recipe_recommendation-main/api/api.py", line 171, in signup
    raise HTTPException(status_code=500, detail=str(e))
fastapi.exceptions.HTTPException: 500: 400: User already exists

2024-12-25 23:31:05,811 - ERROR - 
Endpoint: login
URL: No URL
Method: No method
Data: No request data
Error: 500: name 'timedelta' is not defined
Traceback: Traceback (most recent call last):
  File "/home/charbel/Desktop/recipe_recommendation-main/api/api.py", line 191, in login
    access_token_expires = timedelta(minutes=ACCESS_TOKEN_EXPIRE_MINUTES)
                           ^^^^^^^^^
NameError: name 'timedelta' is not defined

During handling of the above exception, another exception occurred:

Traceback (most recent call last):
  File "/home/charbel/Desktop/recipe_recommendation-main/api/api.py", line 25, in wrapper
    return await func(*args, **kwargs)
           ^^^^^^^^^^^^^^^^^^^^^^^^^^^
  File "/home/charbel/Desktop/recipe_recommendation-main/api/api.py", line 209, in login
    raise HTTPException(status_code=500, detail=str(e))
fastapi.exceptions.HTTPException: 500: name 'timedelta' is not defined

2024-12-25 23:31:20,165 - ERROR - 
Endpoint: login
URL: No URL
Method: No method
Data: No request data
Error: 500: name 'timedelta' is not defined
Traceback: Traceback (most recent call last):
  File "/home/charbel/Desktop/recipe_recommendation-main/api/api.py", line 191, in login
    access_token_expires = timedelta(minutes=ACCESS_TOKEN_EXPIRE_MINUTES)
                           ^^^^^^^^^
NameError: name 'timedelta' is not defined

During handling of the above exception, another exception occurred:

Traceback (most recent call last):
  File "/home/charbel/Desktop/recipe_recommendation-main/api/api.py", line 25, in wrapper
    return await func(*args, **kwargs)
           ^^^^^^^^^^^^^^^^^^^^^^^^^^^
  File "/home/charbel/Desktop/recipe_recommendation-main/api/api.py", line 209, in login
    raise HTTPException(status_code=500, detail=str(e))
fastapi.exceptions.HTTPException: 500: name 'timedelta' is not defined

2024-12-25 23:32:52,004 - ERROR - 
Endpoint: signup
URL: No URL
Method: No method
Data: No request data
Error: 500: 400: User already exists
Traceback: Traceback (most recent call last):
  File "/home/charbel/Desktop/recipe_recommendation-main/api/api.py", line 166, in signup
    raise HTTPException(status_code=400, detail="User already exists")
fastapi.exceptions.HTTPException: 400: User already exists

During handling of the above exception, another exception occurred:

Traceback (most recent call last):
  File "/home/charbel/Desktop/recipe_recommendation-main/api/api.py", line 26, in wrapper
    return await func(*args, **kwargs)
           ^^^^^^^^^^^^^^^^^^^^^^^^^^^
  File "/home/charbel/Desktop/recipe_recommendation-main/api/api.py", line 172, in signup
    raise HTTPException(status_code=500, detail=str(e))
fastapi.exceptions.HTTPException: 500: 400: User already exists

2024-12-25 23:32:52,021 - ERROR - 
Endpoint: login
URL: No URL
Method: No method
Data: No request data
Error: 500: type object 'datetime.datetime' has no attribute 'UTC'
Traceback: Traceback (most recent call last):
  File "/home/charbel/Desktop/recipe_recommendation-main/api/api.py", line 193, in login
    access_token = create_access_token(
                   ^^^^^^^^^^^^^^^^^^^^
  File "/home/charbel/Desktop/recipe_recommendation-main/api/auth_utils.py", line 21, in create_access_token
    expire = datetime.now(datetime.UTC) + expires_delta
                          ^^^^^^^^^^^^
AttributeError: type object 'datetime.datetime' has no attribute 'UTC'

During handling of the above exception, another exception occurred:

Traceback (most recent call last):
  File "/home/charbel/Desktop/recipe_recommendation-main/api/api.py", line 26, in wrapper
    return await func(*args, **kwargs)
           ^^^^^^^^^^^^^^^^^^^^^^^^^^^
  File "/home/charbel/Desktop/recipe_recommendation-main/api/api.py", line 210, in login
    raise HTTPException(status_code=500, detail=str(e))
fastapi.exceptions.HTTPException: 500: type object 'datetime.datetime' has no attribute 'UTC'

2024-12-25 23:34:49,296 - ERROR - 
Endpoint: signup
URL: No URL
Method: No method
Data: No request data
Error: 500: 400: User already exists
Traceback: Traceback (most recent call last):
  File "/home/charbel/Desktop/recipe_recommendation-main/api/api.py", line 166, in signup
    raise HTTPException(status_code=400, detail="User already exists")
fastapi.exceptions.HTTPException: 400: User already exists

During handling of the above exception, another exception occurred:

Traceback (most recent call last):
  File "/home/charbel/Desktop/recipe_recommendation-main/api/api.py", line 26, in wrapper
    return await func(*args, **kwargs)
           ^^^^^^^^^^^^^^^^^^^^^^^^^^^
  File "/home/charbel/Desktop/recipe_recommendation-main/api/api.py", line 172, in signup
    raise HTTPException(status_code=500, detail=str(e))
fastapi.exceptions.HTTPException: 500: 400: User already exists

2024-12-25 23:34:49,336 - ERROR - 
Endpoint: add_recipe_endpoint
URL: No URL
Method: No method
Data: No request data
Error: coroutine raised StopIteration
Traceback: Traceback (most recent call last):
  File "/home/charbel/Desktop/recipe_recommendation-main/api/auth_utils.py", line 47, in wrapper
    request: Request = next(arg for arg in args if isinstance(arg, Request))
                       ^^^^^^^^^^^^^^^^^^^^^^^^^^^^^^^^^^^^^^^^^^^^^^^^^^^^^
StopIteration

The above exception was the direct cause of the following exception:

Traceback (most recent call last):
  File "/home/charbel/Desktop/recipe_recommendation-main/api/api.py", line 26, in wrapper
    return await func(*args, **kwargs)
           ^^^^^^^^^^^^^^^^^^^^^^^^^^^
RuntimeError: coroutine raised StopIteration

2024-12-25 23:37:04,298 - ERROR - 
Endpoint: signup
URL: No URL
Method: No method
Data: No request data
Error: 500: 400: User already exists
Traceback: Traceback (most recent call last):
  File "/home/charbel/Desktop/recipe_recommendation-main/api/api.py", line 166, in signup
    raise HTTPException(status_code=400, detail="User already exists")
fastapi.exceptions.HTTPException: 400: User already exists

During handling of the above exception, another exception occurred:

Traceback (most recent call last):
  File "/home/charbel/Desktop/recipe_recommendation-main/api/api.py", line 26, in wrapper
    return await func(*args, **kwargs)
           ^^^^^^^^^^^^^^^^^^^^^^^^^^^
  File "/home/charbel/Desktop/recipe_recommendation-main/api/api.py", line 172, in signup
    raise HTTPException(status_code=500, detail=str(e))
fastapi.exceptions.HTTPException: 500: 400: User already exists

2024-12-25 23:37:04,333 - ERROR - 
Endpoint: add_recipe_endpoint
URL: No URL
Method: No method
Data: No request data
Error: coroutine raised StopIteration
Traceback: Traceback (most recent call last):
  File "/home/charbel/Desktop/recipe_recommendation-main/api/auth_utils.py", line 47, in wrapper
    request: Request = next(arg for arg in args if isinstance(arg, Request))
                       ^^^^^^^^^^^^^^^^^^^^^^^^^^^^^^^^^^^^^^^^^^^^^^^^^^^^^
StopIteration

The above exception was the direct cause of the following exception:

Traceback (most recent call last):
  File "/home/charbel/Desktop/recipe_recommendation-main/api/api.py", line 26, in wrapper
    return await func(*args, **kwargs)
           ^^^^^^^^^^^^^^^^^^^^^^^^^^^
RuntimeError: coroutine raised StopIteration

2024-12-25 23:39:42,844 - ERROR - 
Endpoint: signup
URL: No URL
Method: No method
Data: No request data
Error: 500: 400: User already exists
Traceback: Traceback (most recent call last):
  File "/home/charbel/Desktop/recipe_recommendation-main/api/api.py", line 164, in signup
    raise HTTPException(status_code=400, detail="User already exists")
fastapi.exceptions.HTTPException: 400: User already exists

During handling of the above exception, another exception occurred:

Traceback (most recent call last):
  File "/home/charbel/Desktop/recipe_recommendation-main/api/api.py", line 26, in wrapper
    return await func(*args, **kwargs)
           ^^^^^^^^^^^^^^^^^^^^^^^^^^^
  File "/home/charbel/Desktop/recipe_recommendation-main/api/api.py", line 170, in signup
    raise HTTPException(status_code=500, detail=str(e))
fastapi.exceptions.HTTPException: 500: 400: User already exists

2024-12-25 23:39:54,643 - ERROR - 
Endpoint: signup
URL: No URL
Method: No method
Data: No request data
Error: 500: 400: User already exists
Traceback: Traceback (most recent call last):
  File "/home/charbel/Desktop/recipe_recommendation-main/api/api.py", line 164, in signup
    raise HTTPException(status_code=400, detail="User already exists")
fastapi.exceptions.HTTPException: 400: User already exists

During handling of the above exception, another exception occurred:

Traceback (most recent call last):
  File "/home/charbel/Desktop/recipe_recommendation-main/api/api.py", line 26, in wrapper
    return await func(*args, **kwargs)
           ^^^^^^^^^^^^^^^^^^^^^^^^^^^
  File "/home/charbel/Desktop/recipe_recommendation-main/api/api.py", line 170, in signup
    raise HTTPException(status_code=500, detail=str(e))
fastapi.exceptions.HTTPException: 500: 400: User already exists

2024-12-25 23:39:54,665 - ERROR - 
Endpoint: add_recipe_endpoint
URL: No URL
Method: No method
Data: No request data
Error: 401: Invalid token: Not enough segments
Traceback: Traceback (most recent call last):
  File "/home/charbel/Desktop/recipe_recommendation-main/api/backend/lib/python3.12/site-packages/jose/jws.py", line 176, in _load
    signing_input, crypto_segment = jwt.rsplit(b".", 1)
    ^^^^^^^^^^^^^^^^^^^^^^^^^^^^^
ValueError: not enough values to unpack (expected 2, got 1)

During handling of the above exception, another exception occurred:

Traceback (most recent call last):
  File "/home/charbel/Desktop/recipe_recommendation-main/api/backend/lib/python3.12/site-packages/jose/jwt.py", line 142, in decode
    payload = jws.verify(token, key, algorithms, verify=verify_signature)
              ^^^^^^^^^^^^^^^^^^^^^^^^^^^^^^^^^^^^^^^^^^^^^^^^^^^^^^^^^^^
  File "/home/charbel/Desktop/recipe_recommendation-main/api/backend/lib/python3.12/site-packages/jose/jws.py", line 70, in verify
    header, payload, signing_input, signature = _load(token)
                                                ^^^^^^^^^^^^
  File "/home/charbel/Desktop/recipe_recommendation-main/api/backend/lib/python3.12/site-packages/jose/jws.py", line 180, in _load
    raise JWSError("Not enough segments")
jose.exceptions.JWSError: Not enough segments

During handling of the above exception, another exception occurred:

Traceback (most recent call last):
  File "/home/charbel/Desktop/recipe_recommendation-main/api/auth_utils.py", line 61, in wrapper
    payload = jwt.decode(token, SECRET_KEY, algorithms=[ALGORITHM])
              ^^^^^^^^^^^^^^^^^^^^^^^^^^^^^^^^^^^^^^^^^^^^^^^^^^^^^
  File "/home/charbel/Desktop/recipe_recommendation-main/api/backend/lib/python3.12/site-packages/jose/jwt.py", line 144, in decode
    raise JWTError(e)
jose.exceptions.JWTError: Not enough segments

During handling of the above exception, another exception occurred:

Traceback (most recent call last):
  File "/home/charbel/Desktop/recipe_recommendation-main/api/api.py", line 26, in wrapper
    return await func(*args, **kwargs)
           ^^^^^^^^^^^^^^^^^^^^^^^^^^^
  File "/home/charbel/Desktop/recipe_recommendation-main/api/auth_utils.py", line 69, in wrapper
    raise HTTPException(status_code=401, detail=f"Invalid token: {str(e)}")
fastapi.exceptions.HTTPException: 401: Invalid token: Not enough segments

2024-12-25 23:40:22,162 - ERROR - 
Endpoint: signup
URL: No URL
Method: No method
Data: No request data
Error: 500: 400: User already exists
Traceback: Traceback (most recent call last):
  File "/home/charbel/Desktop/recipe_recommendation-main/api/api.py", line 164, in signup
    raise HTTPException(status_code=400, detail="User already exists")
fastapi.exceptions.HTTPException: 400: User already exists

During handling of the above exception, another exception occurred:

Traceback (most recent call last):
  File "/home/charbel/Desktop/recipe_recommendation-main/api/api.py", line 26, in wrapper
    return await func(*args, **kwargs)
           ^^^^^^^^^^^^^^^^^^^^^^^^^^^
  File "/home/charbel/Desktop/recipe_recommendation-main/api/api.py", line 170, in signup
    raise HTTPException(status_code=500, detail=str(e))
fastapi.exceptions.HTTPException: 500: 400: User already exists

2024-12-25 23:40:22,181 - ERROR - 
Endpoint: add_recipe_endpoint
URL: No URL
Method: No method
Data: No request data
Error: 401: Invalid token: Signature verification failed.
Traceback: Traceback (most recent call last):
  File "/home/charbel/Desktop/recipe_recommendation-main/api/backend/lib/python3.12/site-packages/jose/jws.py", line 262, in _verify_signature
    raise JWSSignatureError()
jose.exceptions.JWSSignatureError

During handling of the above exception, another exception occurred:

Traceback (most recent call last):
  File "/home/charbel/Desktop/recipe_recommendation-main/api/backend/lib/python3.12/site-packages/jose/jwt.py", line 142, in decode
    payload = jws.verify(token, key, algorithms, verify=verify_signature)
              ^^^^^^^^^^^^^^^^^^^^^^^^^^^^^^^^^^^^^^^^^^^^^^^^^^^^^^^^^^^
  File "/home/charbel/Desktop/recipe_recommendation-main/api/backend/lib/python3.12/site-packages/jose/jws.py", line 73, in verify
    _verify_signature(signing_input, header, signature, key, algorithms)
  File "/home/charbel/Desktop/recipe_recommendation-main/api/backend/lib/python3.12/site-packages/jose/jws.py", line 264, in _verify_signature
    raise JWSError("Signature verification failed.")
jose.exceptions.JWSError: Signature verification failed.

During handling of the above exception, another exception occurred:

Traceback (most recent call last):
  File "/home/charbel/Desktop/recipe_recommendation-main/api/auth_utils.py", line 61, in wrapper
    payload = jwt.decode(token, SECRET_KEY, algorithms=[ALGORITHM])
              ^^^^^^^^^^^^^^^^^^^^^^^^^^^^^^^^^^^^^^^^^^^^^^^^^^^^^
  File "/home/charbel/Desktop/recipe_recommendation-main/api/backend/lib/python3.12/site-packages/jose/jwt.py", line 144, in decode
    raise JWTError(e)
jose.exceptions.JWTError: Signature verification failed.

During handling of the above exception, another exception occurred:

Traceback (most recent call last):
  File "/home/charbel/Desktop/recipe_recommendation-main/api/api.py", line 26, in wrapper
    return await func(*args, **kwargs)
           ^^^^^^^^^^^^^^^^^^^^^^^^^^^
  File "/home/charbel/Desktop/recipe_recommendation-main/api/auth_utils.py", line 69, in wrapper
    raise HTTPException(status_code=401, detail=f"Invalid token: {str(e)}")
fastapi.exceptions.HTTPException: 401: Invalid token: Signature verification failed.

2024-12-25 23:40:31,686 - ERROR - 
Endpoint: signup
URL: No URL
Method: No method
Data: No request data
Error: 500: 400: User already exists
Traceback: Traceback (most recent call last):
  File "/home/charbel/Desktop/recipe_recommendation-main/api/api.py", line 164, in signup
    raise HTTPException(status_code=400, detail="User already exists")
fastapi.exceptions.HTTPException: 400: User already exists

During handling of the above exception, another exception occurred:

Traceback (most recent call last):
  File "/home/charbel/Desktop/recipe_recommendation-main/api/api.py", line 26, in wrapper
    return await func(*args, **kwargs)
           ^^^^^^^^^^^^^^^^^^^^^^^^^^^
  File "/home/charbel/Desktop/recipe_recommendation-main/api/api.py", line 170, in signup
    raise HTTPException(status_code=500, detail=str(e))
fastapi.exceptions.HTTPException: 500: 400: User already exists

2024-12-26 00:15:49,324 - ERROR - 
Endpoint: add_recipe_endpoint
URL: No URL
Method: No method
Data: No request data
Error: 401: Invalid token: Signature has expired.
Traceback: Traceback (most recent call last):
  File "/home/charbel/Desktop/recipe_recommendation-main/api/auth_utils.py", line 61, in wrapper
    payload = jwt.decode(token, SECRET_KEY, algorithms=[ALGORITHM])
              ^^^^^^^^^^^^^^^^^^^^^^^^^^^^^^^^^^^^^^^^^^^^^^^^^^^^^
  File "/home/charbel/Desktop/recipe_recommendation-main/api/backend/lib/python3.12/site-packages/jose/jwt.py", line 157, in decode
    _validate_claims(
  File "/home/charbel/Desktop/recipe_recommendation-main/api/backend/lib/python3.12/site-packages/jose/jwt.py", line 481, in _validate_claims
    _validate_exp(claims, leeway=leeway)
  File "/home/charbel/Desktop/recipe_recommendation-main/api/backend/lib/python3.12/site-packages/jose/jwt.py", line 314, in _validate_exp
    raise ExpiredSignatureError("Signature has expired.")
jose.exceptions.ExpiredSignatureError: Signature has expired.

During handling of the above exception, another exception occurred:

Traceback (most recent call last):
  File "/home/charbel/Desktop/recipe_recommendation-main/api/api.py", line 26, in wrapper
    return await func(*args, **kwargs)
           ^^^^^^^^^^^^^^^^^^^^^^^^^^^
  File "/home/charbel/Desktop/recipe_recommendation-main/api/auth_utils.py", line 69, in wrapper
    raise HTTPException(status_code=401, detail=f"Invalid token: {str(e)}")
fastapi.exceptions.HTTPException: 401: Invalid token: Signature has expired.

2024-12-26 00:16:15,989 - ERROR - 
Endpoint: signup
URL: No URL
Method: No method
Data: No request data
Error: 500: 400: User already exists
Traceback: Traceback (most recent call last):
  File "/home/charbel/Desktop/recipe_recommendation-main/api/api.py", line 164, in signup
    except ValueError as e:
            ^^^^^^^^^^^^^^^^
fastapi.exceptions.HTTPException: 400: User already exists

During handling of the above exception, another exception occurred:

Traceback (most recent call last):
  File "/home/charbel/Desktop/recipe_recommendation-main/api/api.py", line 26, in wrapper
    return await func(*args, **kwargs)
           ^^^^^^^^^^^^^^^^^^^^^^^^^^^
  File "/home/charbel/Desktop/recipe_recommendation-main/api/api.py", line 170, in signup
fastapi.exceptions.HTTPException: 500: 400: User already exists

2024-12-26 00:16:34,693 - ERROR - 
Endpoint: submit_feedback
URL: No URL
Method: No method
Data: No request data
Error: 500: Failed to save feedback: No valid embeddings could be generated from the input
Traceback: Traceback (most recent call last):
  File "/home/charbel/Desktop/recipe_recommendation-main/api/utils.py", line 304, in save_feedback
    """
        
  File "/home/charbel/Desktop/recipe_recommendation-main/api/utils.py", line 282, in update_embedding_from_feedback
    avg_embedding = compute_average_embedding(title_text, image)
                    ^^^^^^^^^^^^^^^^^^^^^^^^^^^^^^^^^^^^^^^^^^^^
  File "/home/charbel/Desktop/recipe_recommendation-main/api/utils.py", line 219, in compute_average_embedding
    raise ValueError("No valid embeddings could be generated from the input")
ValueError: No valid embeddings could be generated from the input

During handling of the above exception, another exception occurred:

Traceback (most recent call last):
  File "/home/charbel/Desktop/recipe_recommendation-main/api/api.py", line 26, in wrapper
    return await func(*args, **kwargs)
           ^^^^^^^^^^^^^^^^^^^^^^^^^^^
  File "/home/charbel/Desktop/recipe_recommendation-main/api/api.py", line 133, in submit_feedback
    except Exception as e:
  File "/home/charbel/Desktop/recipe_recommendation-main/api/utils.py", line 306, in save_feedback
    # Convert Feedback model to dictionary
fastapi.exceptions.HTTPException: 500: Failed to save feedback: No valid embeddings could be generated from the input

2024-12-26 00:18:58,961 - ERROR - 
Endpoint: signup
URL: No URL
Method: No method
Data: No request data
Error: 500: 400: User already exists
Traceback: Traceback (most recent call last):
  File "/home/charbel/Desktop/recipe_recommendation-main/api/api.py", line 162, in signup
    raise HTTPException(status_code=400, detail="User already exists")
fastapi.exceptions.HTTPException: 400: User already exists

During handling of the above exception, another exception occurred:

Traceback (most recent call last):
  File "/home/charbel/Desktop/recipe_recommendation-main/api/api.py", line 26, in wrapper
    return await func(*args, **kwargs)
           ^^^^^^^^^^^^^^^^^^^^^^^^^^^
  File "/home/charbel/Desktop/recipe_recommendation-main/api/api.py", line 168, in signup
    raise HTTPException(status_code=500, detail=str(e))
fastapi.exceptions.HTTPException: 500: 400: User already exists

2024-12-26 00:19:44,445 - ERROR - 
Endpoint: signup
URL: No URL
Method: No method
Data: No request data
Error: 500: 400: User already exists
Traceback: Traceback (most recent call last):
  File "/home/charbel/Desktop/recipe_recommendation-main/api/api.py", line 162, in signup
    raise HTTPException(status_code=400, detail="User already exists")
fastapi.exceptions.HTTPException: 400: User already exists

During handling of the above exception, another exception occurred:

Traceback (most recent call last):
  File "/home/charbel/Desktop/recipe_recommendation-main/api/api.py", line 26, in wrapper
    return await func(*args, **kwargs)
           ^^^^^^^^^^^^^^^^^^^^^^^^^^^
  File "/home/charbel/Desktop/recipe_recommendation-main/api/api.py", line 168, in signup
    raise HTTPException(status_code=500, detail=str(e))
fastapi.exceptions.HTTPException: 500: 400: User already exists

2024-12-26 00:20:05,448 - ERROR - 
Endpoint: signup
URL: No URL
Method: No method
Data: No request data
Error: 500: 400: User already exists
Traceback: Traceback (most recent call last):
  File "/home/charbel/Desktop/recipe_recommendation-main/api/api.py", line 162, in signup
    raise HTTPException(status_code=400, detail="User already exists")
fastapi.exceptions.HTTPException: 400: User already exists

During handling of the above exception, another exception occurred:

Traceback (most recent call last):
  File "/home/charbel/Desktop/recipe_recommendation-main/api/api.py", line 26, in wrapper
    return await func(*args, **kwargs)
           ^^^^^^^^^^^^^^^^^^^^^^^^^^^
  File "/home/charbel/Desktop/recipe_recommendation-main/api/api.py", line 168, in signup
    raise HTTPException(status_code=500, detail=str(e))
fastapi.exceptions.HTTPException: 500: 400: User already exists

2024-12-26 18:26:43,345 - ERROR - 
Endpoint: signup
URL: No URL
Method: No method
Data: No request data
Error: 500: 400: User already exists
Traceback: Traceback (most recent call last):
  File "/home/charbel/Desktop/recipe_recommendation-main/api/api.py", line 172, in signup
    raise HTTPException(status_code=400, detail="User already exists")
fastapi.exceptions.HTTPException: 400: User already exists

During handling of the above exception, another exception occurred:

Traceback (most recent call last):
  File "/home/charbel/Desktop/recipe_recommendation-main/api/api.py", line 26, in wrapper
    return await func(*args, **kwargs)
           ^^^^^^^^^^^^^^^^^^^^^^^^^^^
  File "/home/charbel/Desktop/recipe_recommendation-main/api/api.py", line 178, in signup
    raise HTTPException(status_code=500, detail=str(e))
fastapi.exceptions.HTTPException: 500: 400: User already exists

2024-12-26 18:26:47,157 - ERROR - 
Endpoint: signup
URL: No URL
Method: No method
Data: No request data
Error: 500: 400: User already exists
Traceback: Traceback (most recent call last):
  File "/home/charbel/Desktop/recipe_recommendation-main/api/api.py", line 172, in signup
    raise HTTPException(status_code=400, detail="User already exists")
fastapi.exceptions.HTTPException: 400: User already exists

During handling of the above exception, another exception occurred:

Traceback (most recent call last):
  File "/home/charbel/Desktop/recipe_recommendation-main/api/api.py", line 26, in wrapper
    return await func(*args, **kwargs)
           ^^^^^^^^^^^^^^^^^^^^^^^^^^^
  File "/home/charbel/Desktop/recipe_recommendation-main/api/api.py", line 178, in signup
    raise HTTPException(status_code=500, detail=str(e))
fastapi.exceptions.HTTPException: 500: 400: User already exists

2024-12-26 18:26:47,252 - ERROR - 
Endpoint: submit_feedback
URL: No URL
Method: No method
Data: No request data
Error: 500: Error submitting feedback: 500: Failed to index feedback
Traceback: Traceback (most recent call last):
  File "/home/charbel/Desktop/recipe_recommendation-main/api/api.py", line 142, in submit_feedback
    raise HTTPException(status_code=500, detail="Failed to index feedback")
fastapi.exceptions.HTTPException: 500: Failed to index feedback

During handling of the above exception, another exception occurred:

Traceback (most recent call last):
  File "/home/charbel/Desktop/recipe_recommendation-main/api/api.py", line 26, in wrapper
    return await func(*args, **kwargs)
           ^^^^^^^^^^^^^^^^^^^^^^^^^^^
  File "/home/charbel/Desktop/recipe_recommendation-main/api/auth_utils.py", line 67, in wrapper
    return await func(*args, **kwargs)
           ^^^^^^^^^^^^^^^^^^^^^^^^^^^
  File "/home/charbel/Desktop/recipe_recommendation-main/api/api.py", line 144, in submit_feedback
    raise HTTPException(
fastapi.exceptions.HTTPException: 500: Error submitting feedback: 500: Failed to index feedback

2024-12-26 18:29:25,936 - ERROR - 
Endpoint: signup
URL: No URL
Method: No method
Data: No request data
Error: 500: 400: User already exists
Traceback: Traceback (most recent call last):
  File "/home/charbel/Desktop/recipe_recommendation-main/api/api.py", line 172, in signup
    raise HTTPException(status_code=400, detail="User already exists")
fastapi.exceptions.HTTPException: 400: User already exists

During handling of the above exception, another exception occurred:

Traceback (most recent call last):
  File "/home/charbel/Desktop/recipe_recommendation-main/api/api.py", line 26, in wrapper
    return await func(*args, **kwargs)
           ^^^^^^^^^^^^^^^^^^^^^^^^^^^
  File "/home/charbel/Desktop/recipe_recommendation-main/api/api.py", line 178, in signup
    raise HTTPException(status_code=500, detail=str(e))
fastapi.exceptions.HTTPException: 500: 400: User already exists

2024-12-26 18:29:26,012 - ERROR - 
Endpoint: submit_feedback
URL: No URL
Method: No method
Data: No request data
Error: 500: Error submitting feedback: 500: Failed to index feedback
Traceback: Traceback (most recent call last):
  File "/home/charbel/Desktop/recipe_recommendation-main/api/api.py", line 142, in submit_feedback
    raise HTTPException(status_code=500, detail="Failed to index feedback")
fastapi.exceptions.HTTPException: 500: Failed to index feedback

During handling of the above exception, another exception occurred:

Traceback (most recent call last):
  File "/home/charbel/Desktop/recipe_recommendation-main/api/api.py", line 26, in wrapper
    return await func(*args, **kwargs)
           ^^^^^^^^^^^^^^^^^^^^^^^^^^^
  File "/home/charbel/Desktop/recipe_recommendation-main/api/auth_utils.py", line 67, in wrapper
    return await func(*args, **kwargs)
           ^^^^^^^^^^^^^^^^^^^^^^^^^^^
  File "/home/charbel/Desktop/recipe_recommendation-main/api/api.py", line 144, in submit_feedback
    raise HTTPException(
fastapi.exceptions.HTTPException: 500: Error submitting feedback: 500: Failed to index feedback

2024-12-26 18:33:26,965 - ERROR - 
Endpoint: signup
URL: No URL
Method: No method
Data: No request data
Error: 500: 400: User already exists
Traceback: Traceback (most recent call last):
  File "/home/charbel/Desktop/recipe_recommendation-main/api/api.py", line 172, in signup
    raise HTTPException(status_code=400, detail="User already exists")
fastapi.exceptions.HTTPException: 400: User already exists

During handling of the above exception, another exception occurred:

Traceback (most recent call last):
  File "/home/charbel/Desktop/recipe_recommendation-main/api/api.py", line 26, in wrapper
    return await func(*args, **kwargs)
           ^^^^^^^^^^^^^^^^^^^^^^^^^^^
  File "/home/charbel/Desktop/recipe_recommendation-main/api/api.py", line 178, in signup
    raise HTTPException(status_code=500, detail=str(e))
fastapi.exceptions.HTTPException: 500: 400: User already exists

2024-12-26 18:33:48,858 - ERROR - 
Endpoint: signup
URL: No URL
Method: No method
Data: No request data
Error: 500: 400: User already exists
Traceback: Traceback (most recent call last):
  File "/home/charbel/Desktop/recipe_recommendation-main/api/api.py", line 172, in signup
    raise HTTPException(status_code=400, detail="User already exists")
fastapi.exceptions.HTTPException: 400: User already exists

During handling of the above exception, another exception occurred:

Traceback (most recent call last):
  File "/home/charbel/Desktop/recipe_recommendation-main/api/api.py", line 26, in wrapper
    return await func(*args, **kwargs)
           ^^^^^^^^^^^^^^^^^^^^^^^^^^^
  File "/home/charbel/Desktop/recipe_recommendation-main/api/api.py", line 178, in signup
    raise HTTPException(status_code=500, detail=str(e))
fastapi.exceptions.HTTPException: 500: 400: User already exists

2024-12-26 18:33:48,896 - ERROR - 
Endpoint: submit_feedback
URL: No URL
Method: No method
Data: No request data
Error: 401: Invalid token: Not enough segments
Traceback: Traceback (most recent call last):
  File "/home/charbel/Desktop/recipe_recommendation-main/api/backend/lib/python3.12/site-packages/jose/jws.py", line 176, in _load
    signing_input, crypto_segment = jwt.rsplit(b".", 1)
    ^^^^^^^^^^^^^^^^^^^^^^^^^^^^^
ValueError: not enough values to unpack (expected 2, got 1)

During handling of the above exception, another exception occurred:

Traceback (most recent call last):
  File "/home/charbel/Desktop/recipe_recommendation-main/api/backend/lib/python3.12/site-packages/jose/jwt.py", line 142, in decode
    payload = jws.verify(token, key, algorithms, verify=verify_signature)
              ^^^^^^^^^^^^^^^^^^^^^^^^^^^^^^^^^^^^^^^^^^^^^^^^^^^^^^^^^^^
  File "/home/charbel/Desktop/recipe_recommendation-main/api/backend/lib/python3.12/site-packages/jose/jws.py", line 70, in verify
    header, payload, signing_input, signature = _load(token)
                                                ^^^^^^^^^^^^
  File "/home/charbel/Desktop/recipe_recommendation-main/api/backend/lib/python3.12/site-packages/jose/jws.py", line 180, in _load
    raise JWSError("Not enough segments")
jose.exceptions.JWSError: Not enough segments

During handling of the above exception, another exception occurred:

Traceback (most recent call last):
  File "/home/charbel/Desktop/recipe_recommendation-main/api/auth_utils.py", line 61, in wrapper
    payload = jwt.decode(token, SECRET_KEY, algorithms=[ALGORITHM])
              ^^^^^^^^^^^^^^^^^^^^^^^^^^^^^^^^^^^^^^^^^^^^^^^^^^^^^
  File "/home/charbel/Desktop/recipe_recommendation-main/api/backend/lib/python3.12/site-packages/jose/jwt.py", line 144, in decode
    raise JWTError(e)
jose.exceptions.JWTError: Not enough segments

During handling of the above exception, another exception occurred:

Traceback (most recent call last):
  File "/home/charbel/Desktop/recipe_recommendation-main/api/api.py", line 26, in wrapper
    return await func(*args, **kwargs)
           ^^^^^^^^^^^^^^^^^^^^^^^^^^^
  File "/home/charbel/Desktop/recipe_recommendation-main/api/auth_utils.py", line 69, in wrapper
    raise HTTPException(status_code=401, detail=f"Invalid token: {str(e)}")
fastapi.exceptions.HTTPException: 401: Invalid token: Not enough segments

2024-12-26 18:33:55,060 - ERROR - 
Endpoint: signup
URL: No URL
Method: No method
Data: No request data
Error: 500: 400: User already exists
Traceback: Traceback (most recent call last):
  File "/home/charbel/Desktop/recipe_recommendation-main/api/api.py", line 172, in signup
    raise HTTPException(status_code=400, detail="User already exists")
fastapi.exceptions.HTTPException: 400: User already exists

During handling of the above exception, another exception occurred:

Traceback (most recent call last):
  File "/home/charbel/Desktop/recipe_recommendation-main/api/api.py", line 26, in wrapper
    return await func(*args, **kwargs)
           ^^^^^^^^^^^^^^^^^^^^^^^^^^^
  File "/home/charbel/Desktop/recipe_recommendation-main/api/api.py", line 178, in signup
    raise HTTPException(status_code=500, detail=str(e))
fastapi.exceptions.HTTPException: 500: 400: User already exists

2024-12-26 18:33:55,102 - ERROR - 
Endpoint: submit_feedback
URL: No URL
Method: No method
Data: No request data
Error: 401: Invalid token: Not enough segments
Traceback: Traceback (most recent call last):
  File "/home/charbel/Desktop/recipe_recommendation-main/api/backend/lib/python3.12/site-packages/jose/jws.py", line 176, in _load
    signing_input, crypto_segment = jwt.rsplit(b".", 1)
    ^^^^^^^^^^^^^^^^^^^^^^^^^^^^^
ValueError: not enough values to unpack (expected 2, got 1)

During handling of the above exception, another exception occurred:

Traceback (most recent call last):
  File "/home/charbel/Desktop/recipe_recommendation-main/api/backend/lib/python3.12/site-packages/jose/jwt.py", line 142, in decode
    payload = jws.verify(token, key, algorithms, verify=verify_signature)
              ^^^^^^^^^^^^^^^^^^^^^^^^^^^^^^^^^^^^^^^^^^^^^^^^^^^^^^^^^^^
  File "/home/charbel/Desktop/recipe_recommendation-main/api/backend/lib/python3.12/site-packages/jose/jws.py", line 70, in verify
    header, payload, signing_input, signature = _load(token)
                                                ^^^^^^^^^^^^
  File "/home/charbel/Desktop/recipe_recommendation-main/api/backend/lib/python3.12/site-packages/jose/jws.py", line 180, in _load
    raise JWSError("Not enough segments")
jose.exceptions.JWSError: Not enough segments

During handling of the above exception, another exception occurred:

Traceback (most recent call last):
  File "/home/charbel/Desktop/recipe_recommendation-main/api/auth_utils.py", line 61, in wrapper
    payload = jwt.decode(token, SECRET_KEY, algorithms=[ALGORITHM])
              ^^^^^^^^^^^^^^^^^^^^^^^^^^^^^^^^^^^^^^^^^^^^^^^^^^^^^
  File "/home/charbel/Desktop/recipe_recommendation-main/api/backend/lib/python3.12/site-packages/jose/jwt.py", line 144, in decode
    raise JWTError(e)
jose.exceptions.JWTError: Not enough segments

During handling of the above exception, another exception occurred:

Traceback (most recent call last):
  File "/home/charbel/Desktop/recipe_recommendation-main/api/api.py", line 26, in wrapper
    return await func(*args, **kwargs)
           ^^^^^^^^^^^^^^^^^^^^^^^^^^^
  File "/home/charbel/Desktop/recipe_recommendation-main/api/auth_utils.py", line 69, in wrapper
    raise HTTPException(status_code=401, detail=f"Invalid token: {str(e)}")
fastapi.exceptions.HTTPException: 401: Invalid token: Not enough segments

2024-12-26 18:34:01,241 - ERROR - 
Endpoint: signup
URL: No URL
Method: No method
Data: No request data
Error: 500: 400: User already exists
Traceback: Traceback (most recent call last):
  File "/home/charbel/Desktop/recipe_recommendation-main/api/api.py", line 172, in signup
    raise HTTPException(status_code=400, detail="User already exists")
fastapi.exceptions.HTTPException: 400: User already exists

During handling of the above exception, another exception occurred:

Traceback (most recent call last):
  File "/home/charbel/Desktop/recipe_recommendation-main/api/api.py", line 26, in wrapper
    return await func(*args, **kwargs)
           ^^^^^^^^^^^^^^^^^^^^^^^^^^^
  File "/home/charbel/Desktop/recipe_recommendation-main/api/api.py", line 178, in signup
    raise HTTPException(status_code=500, detail=str(e))
fastapi.exceptions.HTTPException: 500: 400: User already exists

2024-12-26 18:38:05,663 - ERROR - 
Endpoint: signup
URL: No URL
Method: No method
Data: No request data
Error: 500: 400: User already exists
Traceback: Traceback (most recent call last):
  File "/home/charbel/Desktop/recipe_recommendation-main/api/api.py", line 172, in signup
    raise HTTPException(status_code=400, detail="User already exists")
fastapi.exceptions.HTTPException: 400: User already exists

During handling of the above exception, another exception occurred:

Traceback (most recent call last):
  File "/home/charbel/Desktop/recipe_recommendation-main/api/api.py", line 26, in wrapper
    return await func(*args, **kwargs)
           ^^^^^^^^^^^^^^^^^^^^^^^^^^^
  File "/home/charbel/Desktop/recipe_recommendation-main/api/api.py", line 178, in signup
    raise HTTPException(status_code=500, detail=str(e))
fastapi.exceptions.HTTPException: 500: 400: User already exists

2024-12-26 18:39:22,624 - ERROR - 
Endpoint: signup
URL: No URL
Method: No method
Data: No request data
Error: 500: 400: User already exists
Traceback: Traceback (most recent call last):
  File "/home/charbel/Desktop/recipe_recommendation-main/api/api.py", line 172, in signup
    raise HTTPException(status_code=400, detail="User already exists")
fastapi.exceptions.HTTPException: 400: User already exists

During handling of the above exception, another exception occurred:

Traceback (most recent call last):
  File "/home/charbel/Desktop/recipe_recommendation-main/api/api.py", line 26, in wrapper
    return await func(*args, **kwargs)
           ^^^^^^^^^^^^^^^^^^^^^^^^^^^
  File "/home/charbel/Desktop/recipe_recommendation-main/api/api.py", line 178, in signup
    raise HTTPException(status_code=500, detail=str(e))
fastapi.exceptions.HTTPException: 500: 400: User already exists

2024-12-26 18:42:40,726 - ERROR - 
Endpoint: signup
URL: No URL
Method: No method
Data: No request data
Error: 500: 400: User already exists
Traceback: Traceback (most recent call last):
  File "/home/charbel/Desktop/recipe_recommendation-main/api/api.py", line 172, in signup
    raise HTTPException(status_code=400, detail="User already exists")
fastapi.exceptions.HTTPException: 400: User already exists

During handling of the above exception, another exception occurred:

Traceback (most recent call last):
  File "/home/charbel/Desktop/recipe_recommendation-main/api/api.py", line 26, in wrapper
    return await func(*args, **kwargs)
           ^^^^^^^^^^^^^^^^^^^^^^^^^^^
  File "/home/charbel/Desktop/recipe_recommendation-main/api/api.py", line 178, in signup
    raise HTTPException(status_code=500, detail=str(e))
fastapi.exceptions.HTTPException: 500: 400: User already exists

2024-12-26 18:46:05,119 - ERROR - 
Endpoint: signup
URL: No URL
Method: No method
Data: No request data
Error: 500: 400: User already exists
Traceback: Traceback (most recent call last):
  File "/home/charbel/Desktop/recipe_recommendation-main/api/api.py", line 172, in signup
    raise HTTPException(status_code=400, detail="User already exists")
fastapi.exceptions.HTTPException: 400: User already exists

During handling of the above exception, another exception occurred:

Traceback (most recent call last):
  File "/home/charbel/Desktop/recipe_recommendation-main/api/api.py", line 26, in wrapper
    return await func(*args, **kwargs)
           ^^^^^^^^^^^^^^^^^^^^^^^^^^^
  File "/home/charbel/Desktop/recipe_recommendation-main/api/api.py", line 178, in signup
    raise HTTPException(status_code=500, detail=str(e))
fastapi.exceptions.HTTPException: 500: 400: User already exists

2024-12-26 18:48:02,151 - ERROR - 
Endpoint: signup
URL: No URL
Method: No method
Data: No request data
Error: 500: 400: User already exists
Traceback: Traceback (most recent call last):
  File "/home/charbel/Desktop/recipe_recommendation-main/api/api.py", line 172, in signup
    raise HTTPException(status_code=400, detail="User already exists")
fastapi.exceptions.HTTPException: 400: User already exists

During handling of the above exception, another exception occurred:

Traceback (most recent call last):
  File "/home/charbel/Desktop/recipe_recommendation-main/api/api.py", line 26, in wrapper
    return await func(*args, **kwargs)
           ^^^^^^^^^^^^^^^^^^^^^^^^^^^
  File "/home/charbel/Desktop/recipe_recommendation-main/api/api.py", line 178, in signup
    raise HTTPException(status_code=500, detail=str(e))
fastapi.exceptions.HTTPException: 500: 400: User already exists

2024-12-26 18:50:57,903 - ERROR - 
Endpoint: signup
URL: No URL
Method: No method
Data: No request data
Error: 500: 400: User already exists
Traceback: Traceback (most recent call last):
  File "/home/charbel/Desktop/recipe_recommendation-main/api/api.py", line 172, in signup
    raise HTTPException(status_code=400, detail="User already exists")
fastapi.exceptions.HTTPException: 400: User already exists

During handling of the above exception, another exception occurred:

Traceback (most recent call last):
  File "/home/charbel/Desktop/recipe_recommendation-main/api/api.py", line 26, in wrapper
    return await func(*args, **kwargs)
           ^^^^^^^^^^^^^^^^^^^^^^^^^^^
  File "/home/charbel/Desktop/recipe_recommendation-main/api/api.py", line 178, in signup
    raise HTTPException(status_code=500, detail=str(e))
fastapi.exceptions.HTTPException: 500: 400: User already exists

2024-12-26 18:51:47,281 - ERROR - 
Endpoint: signup
URL: No URL
Method: No method
Data: No request data
Error: 500: 400: User already exists
Traceback: Traceback (most recent call last):
  File "/home/charbel/Desktop/recipe_recommendation-main/api/api.py", line 172, in signup
    raise HTTPException(status_code=400, detail="User already exists")
fastapi.exceptions.HTTPException: 400: User already exists

During handling of the above exception, another exception occurred:

Traceback (most recent call last):
  File "/home/charbel/Desktop/recipe_recommendation-main/api/api.py", line 26, in wrapper
    return await func(*args, **kwargs)
           ^^^^^^^^^^^^^^^^^^^^^^^^^^^
  File "/home/charbel/Desktop/recipe_recommendation-main/api/api.py", line 178, in signup
    raise HTTPException(status_code=500, detail=str(e))
fastapi.exceptions.HTTPException: 500: 400: User already exists

